Workbook

Sheet Decisiones
A1: Decision_ID | B1: Fecha_Decision | C1: Hora_Publicacion | D1: Tipo_Reunion | E1: Regimen_Operativo | F1: Tasa_Anterior | G1: Cambio_pb | H1: Tasa_Nueva | I1: Direccion_Decision | J1: Decision_Unanime | K1: Numero_Disensos | L1: Comunicado_URL | M1: Minuta_URL | N1: Observaciones
A2: D20000118 | B2: 36543 | D2: Ordinaria | E2: Objetivo de saldos/condiciones monetarias | I2: No disponible | J2: No disponible | L2: https://www.banxico.org.mx/publicaciones-y-prensa/anuncios-de-las-decisiones-de-politica-monetaria/{13454A37-A216-337E-9BEE-60EC43BDB91D}.pdf | N2: Régimen: Objetivo de saldos/condiciones monetarias.
A3: D20000516 | B3: 36662 | D3: Ordinaria | E3: Objetivo de saldos/condiciones monetarias | I3: No disponible | J3: No disponible | L3: https://www.banxico.org.mx/publicaciones-y-prensa/anuncios-de-las-decisiones-de-politica-monetaria/{2A7425E0-0B60-E7EC-E099-5384C9A7A018}.pdf | N3: Régimen: Objetivo de saldos/condiciones monetarias.
A4: D20000626 | B4: 36703 | D4: Ordinaria | E4: Objetivo de saldos/condiciones monetarias | I4: No disponible | J4: No disponible | L4: https://www.banxico.org.mx/publicaciones-y-prensa/anuncios-de-las-decisiones-de-politica-monetaria/{71B5EA84-D683-03C6-D004-D4E1C4BB9236}.pdf | N4: Régimen: Objetivo de saldos/condiciones monetarias.
A5: D20000731 | B5: 36738 | D5: Ordinaria | E5: Objetivo de saldos/condiciones monetarias | I5: No disponible | J5: No disponible | L5: https://www.banxico.org.mx/publicaciones-y-prensa/anuncios-de-las-decisiones-de-politica-monetaria/{4187E97F-C8B7-1EC6-5FCA-8E309EB909FA}.pdf | N5: Régimen: Objetivo de saldos/condiciones monetarias.
A6: D20001017 | B6: 36816 | D6: Ordinaria | E6: Objetivo de saldos/condiciones monetarias | I6: No disponible | J6: No disponible | L6: https://www.banxico.org.mx/publicaciones-y-prensa/anuncios-de-las-decisiones-de-politica-monetaria/{473E1E72-9133-9FCE-DE83-3D82D61B22FD}.pdf | N6: Régimen: Objetivo de saldos/condiciones monetarias.
A7: D20001110 | B7: 36840 | D7: Ordinaria | E7: Objetivo de saldos/condiciones monetarias | I7: No disponible | J7: No disponible | L7: https://www.banxico.org.mx/publicaciones-y-prensa/anuncios-de-las-decisiones-de-politica-monetaria/{C416157F-C815-5F7E-2C50-E22173121854}.pdf | N7: Régimen: Objetivo de saldos/condiciones monetarias.
A8: D20010112 | B8: 36903 | D8: Ordinaria | E8: Objetivo de saldos/condiciones monetarias | I8: No disponible | J8: No disponible | L8: https://www.banxico.org.mx/publicaciones-y-prensa/anuncios-de-las-decisiones-de-politica-monetaria/{33EAA3B9-4E3C-E0E0-D92C-CA453FA05B8A}.pdf | N8: Régimen: Objetivo de saldos/condiciones monetarias.
A9: D20010518 | B9: 37029 | D9: Ordinaria | E9: Objetivo de saldos/condiciones monetarias | I9: No disponible | J9: No disponible | L9: https://www.banxico.org.mx/publicaciones-y-prensa/anuncios-de-las-decisiones-de-politica-monetaria/{A6967738-A7E8-F18B-82F7-FDE8339B823F}.pdf | N9: Régimen: Objetivo de saldos/condiciones monetarias.
A10: D20010731 | B10: 37103 | D10: Ordinaria | E10: Objetivo de saldos/condiciones monetarias | I10: No disponible | J10: No disponible | L10: https://www.banxico.org.mx/publicaciones-y-prensa/anuncios-de-las-decisiones-de-politica-monetaria/{8AE342BE-6BE0-4B37-37DA-421AFAC33517}.pdf | N10: Régimen: Objetivo de saldos/condiciones monetarias.
A11: D20020208 | B11: 37295 | D11: Ordinaria | E11: Objetivo de saldos/condiciones monetarias | I11: No disponible | J11: No disponible | L11: https://www.banxico.org.mx/publicaciones-y-prensa/anuncios-de-las-decisiones-de-politica-monetaria/{E69CD9F3-41CC-5A19-23D1-0FA9917C78AE}.pdf | N11: Régimen: Objetivo de saldos/condiciones monetarias.
A12: D20020412 | B12: 37358 | D12: Ordinaria | E12: Objetivo de saldos/condiciones monetarias | I12: No disponible | J12: No disponible | L12: https://www.banxico.org.mx/publicaciones-y-prensa/anuncios-de-las-decisiones-de-politica-monetaria/{94E7DC25-3B3D-9AE5-756A-7FB3952F88E0}.pdf | N12: Régimen: Objetivo de saldos/condiciones monetarias.
A13: D20020923 | B13: 37522 | D13: Ordinaria | E13: Objetivo de saldos/condiciones monetarias | I13: No disponible | J13: No disponible | L13: https://www.banxico.org.mx/publicaciones-y-prensa/anuncios-de-las-decisiones-de-politica-monetaria/{D9325B84-9524-BF31-DCBC-74F77F984DFD}.pdf | N13: Régimen: Objetivo de saldos/condiciones monetarias.
... A15: D20030110 | B15: 37631 | D15: Ordinaria | E15: Objetivo de saldos/condiciones monetarias | I15: No disponible | J15: No disponible | L15: https://www.banxico.org.mx/publicaciones-y-prensa/anuncios-de-las-decisiones-de-politica-monetaria/{D0207EEA-BC77-B4A8-1C46-ED4DF7881EB1}.pdf | N15: Régimen: Objetivo de saldos/condiciones monetarias.
A16: D20030124 | B16: 37645 | D16: Ordinaria | E16: Objetivo de saldos/condiciones monetarias | G16: 0 | I16: Sin cambio | J16: No disponible | L16: https://www.banxico.org.mx/publicaciones-y-prensa/anuncios-de-las-decisiones-de-politica-monetaria/{0F16A072-22DA-49AB-DB42-911DB5C73606}.pdf | N16: Régimen: Objetivo de saldos/condiciones monetarias.
A17: D20030207 | B17: 37659 | D17: Ordinaria | E17: Objetivo de saldos/condiciones monetarias | I17: No disponible | J17: No disponible | L17: https://www.banxico.org.mx/publicaciones-y-prensa/anuncios-de-las-decisiones-de-politica-monetaria/{E073CD3D-5DCE-7CFF-5329-235F5BC39AF8}.pdf | N17: Régimen: Objetivo de saldos/condiciones monetarias.
A18: D20030221 | B18: 37673 | D18: Ordinaria | E18: Objetivo de saldos/condiciones monetarias | G18: 0 | I18: Sin cambio | J18: No disponible | L18: https://www.banxico.org.mx/publicaciones-y-prensa/anuncios-de-las-decisiones-de-politica-monetaria/{764BD9A2-41E0-2672-F90A-9F06F60FA441}.pdf | N18: Régimen: Objetivo de saldos/condiciones monetarias.
A19: D20030328 | B19: 37708 | D19: Ordinaria | E19: Objetivo de saldos/condiciones monetarias | I19: No disponible | J19: No disponible | L19: https://www.banxico.org.mx/publicaciones-y-prensa/anuncios-de-las-decisiones-de-politica-monetaria/{9D48A960-F722-427B-F851-9C3468F98E70}.pdf | N19: Régimen: Objetivo de saldos/condiciones monetarias.
A20: D20030425 | B20: 37736 | D20: Ordinaria | E20: Objetivo de saldos/condiciones monetarias | G20: 0 | I20: Sin cambio | J20: No disponible | L20: https://www.banxico.org.mx/publicaciones-y-prensa/anuncios-de-las-decisiones-de-politica-monetaria/{F852BA83-BE9B-5D3B-6FBB-72B4C3A657E8}.pdf | N20: Régimen: Objetivo de saldos/condiciones monetarias.
A21: D20030523 | B21: 37764 | D21: Ordinaria | E21: Objetivo de saldos/condiciones monetarias | G21: 0 | I21: Sin cambio | J21: No disponible | L21: https://www.banxico.org.mx/publicaciones-y-prensa/anuncios-de-las-decisiones-de-politica-monetaria/{75FAED4F-1FD7-B184-68DA-459DB0D2C9D8}.pdf | N21: Régimen: Objetivo de saldos/condiciones monetarias.
A22: D20030627 | B22: 37799 | D22: Ordinaria | E22: Objetivo de saldos/condiciones monetarias | G22: 0 | I22: Sin cambio | J22: No disponible | L22: https://www.banxico.org.mx/publicaciones-y-prensa/anuncios-de-las-decisiones-de-politica-monetaria/{EC4DDDDD-1C8D-B612-4BA6-C7063526FB16}.pdf | N22: Régimen: Objetivo de saldos/condiciones monetarias.
A23: D20030725 | B23: 37827 | D23: Ordinaria | E23: Objetivo de saldos/condiciones monetarias | G23: 0 | I23: Sin cambio | J23: No disponible | L23: https://www.banxico.org.mx/publicaciones-y-prensa/anuncios-de-las-decisiones-de-politica-monetaria/{97ACA940-E4CD-D46F-BAD1-57616BDD33A3}.pdf | N23: Régimen: Objetivo de saldos/condiciones monetarias.
A24: D20030822 | B24: 37855 | D24: Ordinaria | E24: Objetivo de saldos/condiciones monetarias | G24: 0 | I24: Sin cambio | J24: No disponible | L24: https://www.banxico.org.mx/publicaciones-y-prensa/anuncios-de-las-decisiones-de-politica-monetaria/{1A0FC36A-5B93-D407-8F37-81F092E441AB}.pdf | N24: Régimen: Objetivo de saldos/condiciones monetarias.
A25: D20030926 | B25: 37890 | D25: Ordinaria | E25: Objetivo de saldos/condiciones monetarias | G25: 0 | I25: Sin cambio | J25: No disponible | L25: https://www.banxico.org.mx/publicaciones-y-prensa/anuncios-de-las-decisiones-de-politica-monetaria/{F749E14A-A807-75EF-7244-FE219AB900D7}.pdf | N25: Régimen: Objetivo de saldos/condiciones monetarias.
A26: D20031024 | B26: 37918 | D26: Ordinaria | E26: Objetivo de saldos/condiciones monetarias | G26: 0 | I26: Sin cambio | J26: No disponible | L26: https://www.banxico.org.mx/publicaciones-y-prensa/anuncios-de-las-decisiones-de-politica-monetaria/{D58BEC23-B731-5A44-21AC-9EE85D0042B9}.pdf | N26: Régimen: Objetivo de saldos/condiciones monetarias.
A27: D20031121 | B27: 37946 | D27: Ordinaria | E27: Objetivo de saldos/condiciones monetarias | G27: 0 | I27: Sin cambio | J27: No disponible | L27: https://www.banxico.org.mx/publicaciones-y-prensa/anuncios-de-las-decisiones-de-politica-monetaria/{2D614537-FF48-23DC-6C86-37C44731CBCF}.pdf | N27: Régimen: Objetivo de saldos/condiciones monetarias.
A28: D20031211 | B28: 37966 | D28: Ordinaria | E28: Objetivo de saldos/condiciones monetarias | G28: 0 | I28: Sin cambio | J28: No disponible | L28: https://www.banxico.org.mx/publicaciones-y-prensa/anuncios-de-las-decisiones-de-politica-monetaria/{3C1A312D-DC4E-E95B-22CB-625EE103A910}.pdf | N28: Régimen: Objetivo de saldos/condiciones monetarias.
A29: D20040123 | B29: 38009 | D29: Ordinaria | E29: Objetivo de saldos/condiciones monetarias | G29: 0 | I29: Sin cambio | J29: No disponible | L29: https://www.banxico.org.mx/publicaciones-y-prensa/anuncios-de-las-decisiones-de-politica-monetaria/{5BC53D5D-A2C9-4EC5-3F41-43BFA99D1EE6}.pdf | N29: Régimen: Objetivo de saldos/condiciones monetarias.
A30: D20040220 | B30: 38037 | D30: Ordinaria | E30: Objetivo de saldos/condiciones monetarias | I30: No disponible | J30: No disponible | L30: https://www.banxico.org.mx/publicaciones-y-prensa/anuncios-de-las-decisiones-de-politica-monetaria/{3C0303EB-EE8A-E272-9FE6-5325D6A72A27}.pdf | N30: Régimen: Objetivo de saldos/condiciones monetarias.
A31: D20040312 | B31: 38058 | D31: Ordinaria | E31: Objetivo de saldos/condiciones monetarias | I31: No disponible | J31: No disponible | L31: https://www.banxico.org.mx/publicaciones-y-prensa/anuncios-de-las-decisiones-de-politica-monetaria/{2CD1A3C7-9E9C-C895-4962-64F7B460D4F8}.pdf | N31: Régimen: Objetivo de saldos/condiciones monetarias.
A32: D20040326 | B32: 38072 | D32: Ordinaria | E32: Objetivo de saldos/condiciones monetarias | G32: 0 | I32: Sin cambio | J32: No disponible | L32: https://www.banxico.org.mx/publicaciones-y-prensa/anuncios-de-las-decisiones-de-politica-monetaria/{E6066F4E-467D-2EC7-CE49-2D3AF7B50008}.pdf | N32: Régimen: Objetivo de saldos/condiciones monetarias.
A33: D20040423 | B33: 38100 | D33: Ordinaria | E33: Objetivo de saldos/condiciones monetarias | G33: 0 | I33: Sin cambio | J33: No disponible | L33: https://www.banxico.org.mx/publicaciones-y-prensa/anuncios-de-las-decisiones-de-politica-monetaria/{DB2FE114-0DC7-BA33-F53D-3B8F0CF69A43}.pdf | N33: Régimen: Objetivo de saldos/condiciones monetarias.
A34: D20040427 | B34: 38104 | D34: Ordinaria | E34: Objetivo de saldos/condiciones monetarias | I34: No disponible | J34: No disponible | L34: https://www.banxico.org.mx/publicaciones-y-prensa/anuncios-de-las-decisiones-de-politica-monetaria/{8EAFAF2F-523B-BC62-4A6B-DD992AFB09D8}.pdf | N34: Régimen: Objetivo de saldos/condiciones monetarias.
A35: D20040528 | B35: 38135 | D35: Ordinaria | E35: Objetivo de saldos/condiciones monetarias | G35: 0 | I35: Sin cambio | J35: No disponible | L35: https://www.banxico.org.mx/publicaciones-y-prensa/anuncios-de-las-decisiones-de-politica-monetaria/{7FD27369-3C10-DD25-AAB6-412265DA768E}.pdf | N35: Régimen: Objetivo de saldos/condiciones monetarias.
A36: D20040625 | B36: 38163 | D36: Ordinaria | E36: Objetivo de saldos/condiciones monetarias | G36: 0 | I36: Sin cambio | J36: No disponible | L36: https://www.banxico.org.mx/publicaciones-y-prensa/anuncios-de-las-decisiones-de-politica-monetaria/{788E18E1-C937-4561-A47E-AF46DABF0F2E}.pdf | N36: Régimen: Objetivo de saldos/condiciones monetarias.
A37: D20040723 | B37: 38191 | D37: Ordinaria | E37: Objetivo de saldos/condiciones monetarias | I37: No disponible | J37: No disponible | L37: https://www.banxico.org.mx/publicaciones-y-prensa/anuncios-de-las-decisiones-de-politica-monetaria/{710117A8-683E-D6CD-BB34-A94007F425A7}.pdf | N37: Régimen: Objetivo de saldos/condiciones monetarias.
A38: D20040827 | B38: 38226 | D38: Ordinaria | E38: Objetivo de saldos/condiciones monetarias | I38: No disponible | J38: No disponible | L38: https://www.banxico.org.mx/publicaciones-y-prensa/anuncios-de-las-decisiones-de-politica-monetaria/{97B669EB-A457-C613-DF07-6FA7F795276C}.pdf | N38: Régimen: Objetivo de saldos/condiciones monetarias.
A39: D20040924 | B39: 38254 | D39: Ordinaria | E39: Objetivo de saldos/condiciones monetarias | I39: No disponible | J39: No disponible | L39: https://www.banxico.org.mx/publicaciones-y-prensa/anuncios-de-las-decisiones-de-politica-monetaria/{4F1865AE-E558-75F0-D5D2-87ECA75DBF9C}.pdf | N39: Régimen: Objetivo de saldos/condiciones monetarias.
A40: D20041022 | B40: 38282 | D40: Ordinaria | E40: Objetivo de saldos/condiciones monetarias | I40: No disponible | J40: No disponible | L40: https://www.banxico.org.mx/publicaciones-y-prensa/anuncios-de-las-decisiones-de-politica-monetaria/{032CBD52-D087-22AF-3711-818376BE3FAD}.pdf | N40: Régimen: Objetivo de saldos/condiciones monetarias.
A41: D20041126 | B41: 38317 | D41: Ordinaria | E41: Objetivo de saldos/condiciones monetarias | I41: No disponible | J41: No disponible | L41: https://www.banxico.org.mx/publicaciones-y-prensa/anuncios-de-las-decisiones-de-politica-monetaria/{CA2823E4-6AFA-B5CD-AC35-466BEA5C593F}.pdf | N41: Régimen: Objetivo de saldos/condiciones monetarias.
...

Sheet Participacion_Junta
A1: Decision_ID | B1: Persona_ID | C1: Cargo | D1: Participacion_Confirmada | E1: Observaciones
A2: D20180517 | B2: P009 | C2: Integrante de la Junta de Gobierno | D2: Presente | E2: Presencia confirmada por la lista de asistentes y/o el voto nominal. Comunicado: https://www.banxico.org.mx/publicaciones-y-prensa/anuncios-de-las-decisiones-de-politica-monetaria/{FA7D3584-6233-EB61-D6D0-420712FB01C2}.pdf | Minuta: https://www.banxico.org.mx/publicaciones-y-prensa/minutas-de-las-decisiones-de-politica-monetaria/{1FC983E2-2499-C296-FE71-85F7ABD67EC3}.pdf
A3: D20180517 | B3: P012 | C3: Integrante de la Junta de Gobierno | D3: Presente | E3: Presencia confirmada por la lista de asistentes y/o el voto nominal. Comunicado: https://www.banxico.org.mx/publicaciones-y-prensa/anuncios-de-las-decisiones-de-politica-monetaria/{FA7D3584-6233-EB61-D6D0-420712FB01C2}.pdf | Minuta: https://www.banxico.org.mx/publicaciones-y-prensa/minutas-de-las-decisiones-de-politica-monetaria/{1FC983E2-2499-C296-FE71-85F7ABD67EC3}.pdf
A4: D20180517 | B4: P013 | C4: Integrante de la Junta de Gobierno | D4: Presente | E4: Presencia confirmada por la lista de asistentes y/o el voto nominal. Comunicado: https://www.banxico.org.mx/publicaciones-y-prensa/anuncios-de-las-decisiones-de-politica-monetaria/{FA7D3584-6233-EB61-D6D0-420712FB01C2}.pdf | Minuta: https://www.banxico.org.mx/publicaciones-y-prensa/minutas-de-las-decisiones-de-politica-monetaria/{1FC983E2-2499-C296-FE71-85F7ABD67EC3}.pdf
A5: D20180517 | B5: P014 | C5: Integrante de la Junta de Gobierno | D5: Presente | E5: Presencia confirmada por la lista de asistentes y/o el voto nominal. Comunicado: https://www.banxico.org.mx/publicaciones-y-prensa/anuncios-de-las-decisiones-de-politica-monetaria/{FA7D3584-6233-EB61-D6D0-420712FB01C2}.pdf | Minuta: https://www.banxico.org.mx/publicaciones-y-prensa/minutas-de-las-decisiones-de-politica-monetaria/{1FC983E2-2499-C296-FE71-85F7ABD67EC3}.pdf
A6: D20180517 | B6: P015 | C6: Integrante de la Junta de Gobierno | D6: Presente | E6: Presencia confirmada por la lista de asistentes y/o el voto nominal. Comunicado: https://www.banxico.org.mx/publicaciones-y-prensa/anuncios-de-las-decisiones-de-politica-monetaria/{FA7D3584-6233-EB61-D6D0-420712FB01C2}.pdf | Minuta: https://www.banxico.org.mx/publicaciones-y-prensa/minutas-de-las-decisiones-de-politica-monetaria/{1FC983E2-2499-C296-FE71-85F7ABD67EC3}.pdf
A7: D20180621 | B7: P009 | C7: Integrante de la Junta de Gobierno | D7: Presente | E7: Presencia confirmada por la lista de asistentes y/o el voto nominal. Comunicado: https://www.banxico.org.mx/publicaciones-y-prensa/anuncios-de-las-decisiones-de-politica-monetaria/{32F5F0C4-9EE7-8BB9-3AE0-291882583F3B}.pdf | Minuta: https://www.banxico.org.mx/publicaciones-y-prensa/minutas-de-las-decisiones-de-politica-monetaria/{9D52CB8A-4EA3-F381-42CC-B4A5E02E76E1}.pdf
A8: D20180621 | B8: P012 | C8: Integrante de la Junta de Gobierno | D8: Presente | E8: Presencia confirmada por la lista de asistentes y/o el voto nominal. Comunicado: https://www.banxico.org.mx/publicaciones-y-prensa/anuncios-de-las-decisiones-de-politica-monetaria/{32F5F0C4-9EE7-8BB9-3AE0-291882583F3B}.pdf | Minuta: https://www.banxico.org.mx/publicaciones-y-prensa/minutas-de-las-decisiones-de-politica-monetaria/{9D52CB8A-4EA3-F381-42CC-B4A5E02E76E1}.pdf
A9: D20180621 | B9: P013 | C9: Integrante de la Junta de Gobierno | D9: Presente | E9: Presencia confirmada por la lista de asistentes y/o el voto nominal. Comunicado: https://www.banxico.org.mx/publicaciones-y-prensa/anuncios-de-las-decisiones-de-politica-monetaria/{32F5F0C4-9EE7-8BB9-3AE0-291882583F3B}.pdf | Minuta: https://www.banxico.org.mx/publicaciones-y-prensa/minutas-de-las-decisiones-de-politica-monetaria/{9D52CB8A-4EA3-F381-42CC-B4A5E02E76E1}.pdf
A10: D20180621 | B10: P014 | C10: Integrante de la Junta de Gobierno | D10: Presente | E10: Presencia confirmada por la lista de asistentes y/o el voto nominal. Comunicado: https://www.banxico.org.mx/publicaciones-y-prensa/anuncios-de-las-decisiones-de-politica-monetaria/{32F5F0C4-9EE7-8BB9-3AE0-291882583F3B}.pdf | Minuta: https://www.banxico.org.mx/publicaciones-y-prensa/minutas-de-las-decisiones-de-politica-monetaria/{9D52CB8A-4EA3-F381-42CC-B4A5E02E76E1}.pdf
A11: D20180621 | B11: P015 | C11: Integrante de la Junta de Gobierno | D11: Presente | E11: Presencia confirmada por la lista de asistentes y/o el voto nominal. Comunicado: https://www.banxico.org.mx/publicaciones-y-prensa/anuncios-de-las-decisiones-de-politica-monetaria/{32F5F0C4-9EE7-8BB9-3AE0-291882583F3B}.pdf | Minuta: https://www.banxico.org.mx/publicaciones-y-prensa/minutas-de-las-decisiones-de-politica-monetaria/{9D52CB8A-4EA3-F381-42CC-B4A5E02E76E1}.pdf
A12: D20180802 | B12: P009 | C12: Integrante de la Junta de Gobierno | D12: Presente | E12: Presencia confirmada por la lista de asistentes y/o el voto nominal. Comunicado: https://www.banxico.org.mx/publicaciones-y-prensa/anuncios-de-las-decisiones-de-politica-monetaria/{B0E8D2FC-D7D2-F62C-E385-936DB840A68A}.pdf | Minuta: https://www.banxico.org.mx/publicaciones-y-prensa/minutas-de-las-decisiones-de-politica-monetaria/{BC265005-129F-A5FD-309A-229CC8559229}.pdf
... A26: D20181115 | B26: P015 | C26: Integrante de la Junta de Gobierno | D26: Presente | E26: Presencia confirmada por la lista de asistentes y/o el voto nominal. Comunicado: https://www.banxico.org.mx/publicaciones-y-prensa/anuncios-de-las-decisiones-de-politica-monetaria/{759F9C79-B40F-CD69-E10F-C56C3265923A}.pdf | Minuta: https://www.banxico.org.mx/publicaciones-y-prensa/minutas-de-las-decisiones-de-politica-monetaria/{E71098EA-AC1E-45CB-F1FC-1BCA43571239}.pdf
A27: D20181220 | C27: Integrante de la Junta de Gobierno | D27: Vacante | E27: Vacante documentada entre la renuncia efectiva de Roberto del Cueto y la designación de Gerardo Esquivel. Fuentes oficiales: https://www.banxico.org.mx/publicaciones-y-prensa/miscelaneos/%7BC5A7D143-40F7-225C-9512-BF9225502B23%7D.pdf | https://www.banxico.org.mx/publicaciones-y-prensa/miscelaneos/%7BD37EA8D9-E439-1416-06B2-539CF2DC3B90%7D.pdf
A28: D20181220 | B28: P012 | C28: Integrante de la Junta de Gobierno | D28: Presente | E28: Presencia confirmada por la lista de asistentes y/o el voto nominal. Comunicado: https://www.banxico.org.mx/publicaciones-y-prensa/anuncios-de-las-decisiones-de-politica-monetaria/{0CB97688-9500-D1A2-A000-C60DAF3E853F}.pdf | Minuta: https://www.banxico.org.mx/publicaciones-y-prensa/minutas-de-las-decisiones-de-politica-monetaria/{5EC61A9B-E408-3DA8-C647-97B441EC6D76}.pdf
A29: D20181220 | B29: P013 | C29: Integrante de la Junta de Gobierno | D29: Presente | E29: Presencia confirmada por la lista de asistentes y/o el voto nominal. Comunicado: https://www.banxico.org.mx/publicaciones-y-prensa/anuncios-de-las-decisiones-de-politica-monetaria/{0CB97688-9500-D1A2-A000-C60DAF3E853F}.pdf | Minuta: https://www.banxico.org.mx/publicaciones-y-prensa/minutas-de-las-decisiones-de-politica-monetaria/{5EC61A9B-E408-3DA8-C647-97B441EC6D76}.pdf
A30: D20181220 | B30: P014 | C30: Integrante de la Junta de Gobierno | D30: Presente | E30: Presencia confirmada por la lista de asistentes y/o el voto nominal. Comunicado: https://www.banxico.org.mx/publicaciones-y-prensa/anuncios-de-las-decisiones-de-politica-monetaria/{0CB97688-9500-D1A2-A000-C60DAF3E853F}.pdf | Minuta: https://www.banxico.org.mx/publicaciones-y-prensa/minutas-de-las-decisiones-de-politica-monetaria/{5EC61A9B-E408-3DA8-C647-97B441EC6D76}.pdf
A31: D20181220 | B31: P015 | C31: Integrante de la Junta de Gobierno | D31: Presente | E31: Presencia confirmada por la lista de asistentes y/o el voto nominal. Comunicado: https://www.banxico.org.mx/publicaciones-y-prensa/anuncios-de-las-decisiones-de-politica-monetaria/{0CB97688-9500-D1A2-A000-C60DAF3E853F}.pdf | Minuta: https://www.banxico.org.mx/publicaciones-y-prensa/minutas-de-las-decisiones-de-politica-monetaria/{5EC61A9B-E408-3DA8-C647-97B441EC6D76}.pdf
A32: D20190207 | B32: P013 | C32: Integrante de la Junta de Gobierno | D32: Presente | E32: Presencia confirmada por la lista de asistentes y/o el voto nominal. Comunicado: https://www.banxico.org.mx/publicaciones-y-prensa/anuncios-de-las-decisiones-de-politica-monetaria/{066D3F9D-6038-F9FD-88C6-DFE4977DF0D3}.pdf | Minuta: https://www.banxico.org.mx/publicaciones-y-prensa/minutas-de-las-decisiones-de-politica-monetaria/{A63CB66A-5AED-15AE-F534-2D99FB3FA7C9}.pdf
A33: D20190207 | B33: P014 | C33: Integrante de la Junta de Gobierno | D33: Presente | E33: Presencia confirmada por la lista de asistentes y/o el voto nominal. Comunicado: https://www.banxico.org.mx/publicaciones-y-prensa/anuncios-de-las-decisiones-de-politica-monetaria/{066D3F9D-6038-F9FD-88C6-DFE4977DF0D3}.pdf | Minuta: https://www.banxico.org.mx/publicaciones-y-prensa/minutas-de-las-decisiones-de-politica-monetaria/{A63CB66A-5AED-15AE-F534-2D99FB3FA7C9}.pdf
A34: D20190207 | B34: P015 | C34: Integrante de la Junta de Gobierno | D34: Presente | E34: Presencia confirmada por la lista de asistentes y/o el voto nominal. Comunicado: https://www.banxico.org.mx/publicaciones-y-prensa/anuncios-de-las-decisiones-de-politica-monetaria/{066D3F9D-6038-F9FD-88C6-DFE4977DF0D3}.pdf | Minuta: https://www.banxico.org.mx/publicaciones-y-prensa/minutas-de-las-decisiones-de-politica-monetaria/{A63CB66A-5AED-15AE-F534-2D99FB3FA7C9}.pdf
A35: D20190207 | B35: P016 | C35: Integrante de la Junta de Gobierno | D35: Presente | E35: Presencia confirmada por la lista de asistentes y/o el voto nominal. Comunicado: https://www.banxico.org.mx/publicaciones-y-prensa/anuncios-de-las-decisiones-de-politica-monetaria/{066D3F9D-6038-F9FD-88C6-DFE4977DF0D3}.pdf | Minuta: https://www.banxico.org.mx/publicaciones-y-prensa/minutas-de-las-decisiones-de-politica-monetaria/{A63CB66A-5AED-15AE-F534-2D99FB3FA7C9}.pdf
A36: D20190207 | B36: P017 | C36: Integrante de la Junta de Gobierno | D36: Presente | E36: Presencia confirmada por la lista de asistentes y/o el voto nominal. Comunicado: https://www.banxico.org.mx/publicaciones-y-prensa/anuncios-de-las-decisiones-de-politica-monetaria/{066D3F9D-6038-F9FD-88C6-DFE4977DF0D3}.pdf | Minuta: https://www.banxico.org.mx/publicaciones-y-prensa/minutas-de-las-decisiones-de-politica-monetaria/{A63CB66A-5AED-15AE-F534-2D99FB3FA7C9}.pdf
A37: D20190328 | B37: P013 | C37: Integrante de la Junta de Gobierno | D37: Presente | E37: Presencia confirmada por la lista de asistentes y/o el voto nominal. Comunicado: https://www.banxico.org.mx/publicaciones-y-prensa/anuncios-de-las-decisiones-de-politica-monetaria/{0F4AB746-781C-0D0A-5E3F-D5D28B14040C}.pdf | Minuta: https://www.banxico.org.mx/publicaciones-y-prensa/minutas-de-las-decisiones-de-politica-monetaria/{FB16B517-D1BF-D281-60B9-C3552469117C}.pdf
A38: D20190328 | B38: P014 | C38: Integrante de la Junta de Gobierno | D38: Presente | E38: Presencia confirmada por la lista de asistentes y/o el voto nominal. Comunicado: https://www.banxico.org.mx/publicaciones-y-prensa/anuncios-de-las-decisiones-de-politica-monetaria/{0F4AB746-781C-0D0A-5E3F-D5D28B14040C}.pdf | Minuta: https://www.banxico.org.mx/publicaciones-y-prensa/minutas-de-las-decisiones-de-politica-monetaria/{FB16B517-D1BF-D281-60B9-C3552469117C}.pdf
A39: D20190328 | B39: P015 | C39: Integrante de la Junta de Gobierno | D39: Presente | E39: Presencia confirmada por la lista de asistentes y/o el voto nominal. Comunicado: https://www.banxico.org.mx/publicaciones-y-prensa/anuncios-de-las-decisiones-de-politica-monetaria/{0F4AB746-781C-0D0A-5E3F-D5D28B14040C}.pdf | Minuta: https://www.banxico.org.mx/publicaciones-y-prensa/minutas-de-las-decisiones-de-politica-monetaria/{FB16B517-D1BF-D281-60B9-C3552469117C}.pdf
... A346: D20260924 | B346: P021 | C346: Integrante de la Junta de Gobierno | D346: Presente | E346: Comunicado oficial: https://www.banxico.org.mx/publicaciones-y-prensa/anuncios-de-las-decisiones-de-politica-monetaria/{7D0BDB6E-E519-9C69-04AA-ABD4D31E4850}.pdf. El comunicado declara presencia de todos los miembros y decisión unánime.

Sheet Votaciones
A1: Decision_ID | B1: Persona_ID | C1: Voto | D1: Tipo_Voto | E1: Nivel_Identificacion | F1: Observaciones
A2: D20130906 | C2: No disponible | D2: No identificable | E2: Anónimo | F2: El documento oficial declara mayoría/disenso sin identificación nominal suficiente.
A3: D20180517 | B3: P009 | C3: Mantener | D3: Consenso | E3: Público | F3: Voto nominal explícito en la sección 4. VOTACIÓN de la minuta oficial. Minuta oficial: https://www.banxico.org.mx/publicaciones-y-prensa/minutas-de-las-decisiones-de-politica-monetaria/{1FC983E2-2499-C296-FE71-85F7ABD67EC3}.pdf
A4: D20180517 | B4: P012 | C4: Mantener | D4: Consenso | E4: Público | F4: Voto nominal explícito en la sección 4. VOTACIÓN de la minuta oficial. Minuta oficial: https://www.banxico.org.mx/publicaciones-y-prensa/minutas-de-las-decisiones-de-politica-monetaria/{1FC983E2-2499-C296-FE71-85F7ABD67EC3}.pdf
A5: D20180517 | B5: P013 | C5: Mantener | D5: Consenso | E5: Público | F5: Voto nominal explícito en la sección 4. VOTACIÓN de la minuta oficial. Minuta oficial: https://www.banxico.org.mx/publicaciones-y-prensa/minutas-de-las-decisiones-de-politica-monetaria/{1FC983E2-2499-C296-FE71-85F7ABD67EC3}.pdf
A6: D20180517 | B6: P014 | C6: Mantener | D6: Consenso | E6: Público | F6: Voto nominal explícito en la sección 4. VOTACIÓN de la minuta oficial. Minuta oficial: https://www.banxico.org.mx/publicaciones-y-prensa/minutas-de-las-decisiones-de-politica-monetaria/{1FC983E2-2499-C296-FE71-85F7ABD67EC3}.pdf
A7: D20180517 | B7: P015 | C7: Mantener | D7: Consenso | E7: Público | F7: Voto nominal explícito en la sección 4. VOTACIÓN de la minuta oficial. Minuta oficial: https://www.banxico.org.mx/publicaciones-y-prensa/minutas-de-las-decisiones-de-politica-monetaria/{1FC983E2-2499-C296-FE71-85F7ABD67EC3}.pdf
A8: D20180621 | B8: P009 | C8: Subir | D8: Consenso | E8: Público | F8: Voto nominal explícito en la sección 4. VOTACIÓN de la minuta oficial. Minuta oficial: https://www.banxico.org.mx/publicaciones-y-prensa/minutas-de-las-decisiones-de-politica-monetaria/{9D52CB8A-4EA3-F381-42CC-B4A5E02E76E1}.pdf
A9: D20180621 | B9: P012 | C9: Subir | D9: Consenso | E9: Público | F9: Voto nominal explícito en la sección 4. VOTACIÓN de la minuta oficial. Minuta oficial: https://www.banxico.org.mx/publicaciones-y-prensa/minutas-de-las-decisiones-de-politica-monetaria/{9D52CB8A-4EA3-F381-42CC-B4A5E02E76E1}.pdf
A10: D20180621 | B10: P013 | C10: Subir | D10: Consenso | E10: Público | F10: Voto nominal explícito en la sección 4. VOTACIÓN de la minuta oficial. Minuta oficial: https://www.banxico.org.mx/publicaciones-y-prensa/minutas-de-las-decisiones-de-politica-monetaria/{9D52CB8A-4EA3-F381-42CC-B4A5E02E76E1}.pdf
A11: D20180621 | B11: P014 | C11: Subir | D11: Consenso | E11: Público | F11: Voto nominal explícito en la sección 4. VOTACIÓN de la minuta oficial. Minuta oficial: https://www.banxico.org.mx/publicaciones-y-prensa/minutas-de-las-decisiones-de-politica-monetaria/{9D52CB8A-4EA3-F381-42CC-B4A5E02E76E1}.pdf
A12: D20180621 | B12: P015 | C12: Subir | D12: Consenso | E12: Público | F12: Voto nominal explícito en la sección 4. VOTACIÓN de la minuta oficial. Minuta oficial: https://www.banxico.org.mx/publicaciones-y-prensa/minutas-de-las-decisiones-de-politica-monetaria/{9D52CB8A-4EA3-F381-42CC-B4A5E02E76E1}.pdf
A13: D20180802 | B13: P009 | C13: Mantener | D13: Consenso | E13: Público | F13: Voto nominal explícito en la sección 4. VOTACIÓN de la minuta oficial. Minuta oficial: https://www.banxico.org.mx/publicaciones-y-prensa/minutas-de-las-decisiones-de-politica-monetaria/{BC265005-129F-A5FD-309A-229CC8559229}.pdf
A14: D20180802 | B14: P012 | C14: Mantener | D14: Consenso | E14: Público | F14: Voto nominal explícito en la sección 4. VOTACIÓN de la minuta oficial. Minuta oficial: https://www.banxico.org.mx/publicaciones-y-prensa/minutas-de-las-decisiones-de-politica-monetaria/{BC265005-129F-A5FD-309A-229CC8559229}.pdf
... A346: D20260924 | B346: P021 | C346: Mantener | D346: Consenso | E346: Público | F346: Comunicado oficial: https://www.banxico.org.mx/publicaciones-y-prensa/anuncios-de-las-decisiones-de-politica-monetaria/{7D0BDB6E-E519-9C69-04AA-ABD4D31E4850}.pdf. El comunicado declara presencia de todos los miembros y decisión unánime.

Sheet Personas
A1: Persona_ID | B1: Nombre
A2: P001 | B2: Miguel Mancera Aguayo
A3: P002 | B3: Ariel Buira Seira
A4: P003 | B4: Francisco Gil Díaz
A5: P004 | B5: Guillermo Güémez García
A6: P005 | B6: Jesús Marcos Yacamán
A7: P006 | B7: José Julián Sidaoui Dib
A8: P007 | B8: Everardo Elizondo Almaguer
A9: P008 | B9: Guillermo Ortiz Martínez
A10: P009 | B10: Roberto del Cueto Legaspi
A11: P010 | B11: Manuel Sánchez González
A12: P011 | B12: Agustín Carstens Carstens
... A30: P029 | B30: Luis Videgaray Caso

Sheet Validaciones
A1: Tipo | B1: Decision_ID | C1: Detalle | D1: Severidad
A2: Control de nombramientos no ejecutable | C2: La tabla proporcionada contiene Persona_ID y nombres, pero no fechas de inicio/fin de nombramiento. No se infirieron periodos. | D2: Limitación

Sheet Cobertura
A1: Radar BM · Cobertura del Libro Maestro
A3: Indicador | B3: Valor
A4: Primera decisión | B4: =MIN(Decisiones!B2:B237) -> 36543
A5: Última decisión | B5: 46240
A6: Total de decisiones | B6: 237
A7: Reuniones ordinarias | B7: 234
A8: Reuniones extraordinarias | B8: 3
A9: Decisiones unánimes | B9: 80
A10: Decisiones con disenso | B10: 33
A11: Resultado no disponible | B11: 124
A12: Votos públicos | B12: 339
A13: Votos parciales | B13: =COUNTIF(Votaciones!E2:E336,"Parcial") -> 0
A14: Votos anónimos | B14: =COUNTIF(Votaciones!E2:E336,"Anónimo") -> 1
A16: Fuentes oficiales y criterio
A17: https://www.banxico.org.mx/publicaciones-y-prensa/anuncios-de-las-decisiones-de-politica-monetaria/anuncios-politica-monetaria-t.html
A18: https://www.banxico.org.mx/publicaciones-y-prensa/minutas-de-las-decisiones-de-politica-monetaria/minutas-politica-monetaria-ta.html
A19: No se almacenan copias documentales; se conservan únicamente URL oficiales. Los vacíos históricos permanecen como No disponible.

Sheet Explorador_Decisiones
A1: Radar BM · Explorador analítico de decisiones | X1: Decision_ID interno | Y1: Reserva | Z1: Decision_ID lista | AA1: Fecha selector
A2: Fecha seleccionada | B2: 46289 | E2: ◀ Anterior | F2: =IFERROR(INDEX(Decisiones!$B$2:$B$239,MATCH($X$2,Decisiones!$A$2:$A$239,0)-1),"— inicio —") -> 46240 | I2: Siguiente ▶ | J2: =IFERROR(INDEX(Decisiones!$B$2:$B$239,MATCH($X$2,Decisiones!$A$2:$A$239,0)+1),"— final —") -> — final — | X2: =INDEX($Z$2:$Z$258,MATCH($B$2,$AA$2:$AA$258,0)) -> D20260924 | Z2: D20000118 | AA2: 36543
A3: Use el selector amarillo. Toda la interfaz muestra fechas; los identificadores técnicos se conservan únicamente como referencias internas. | Z3: D20000516 | AA3: 36662
Z4: D20000626 | AA4: 36703
Z5: D20000731 | AA5: 36738
Z6: D20001017 | AA6: 36816
Z7: D20001110 | AA7: 36840
Z8: D20010112 | AA8: 36903
Z9: D20010518 | AA9: 37029
Z10: D20010731 | AA10: 37103
Z11: D20020208 | AA11: 37295
Z12: D20020412 | AA12: 37358
Z13: D20020923 | AA13: 37522
Z14: D20021206 | AA14: 37596
Z15: D20030110 | AA15: 37631
... Z18: D20030221 | AA18: 37673
A19: Resumen de la decisión seleccionada | Z19: D20030328 | AA19: 37708
Z20: D20030425 | AA20: 37736
A21: Fecha seleccionada | B21: Decision_ID | C21: Decision_ID | D21: Decision_ID | E21: Fecha | F21: Fecha | G21: Fecha | H21: Fecha | I21: Tipo de reunión | J21: Tipo de reunión | K21: Tipo de reunión | L21: Tipo de reunión | Z21: D20030523 | AA21: 37764
A22: =INDEX(Decisiones!$B$2:$B$239,MATCH($X$2,Decisiones!$A$2:$A$239,0)) -> 46289 | E22: =IFERROR(INDEX(Decisiones!$B$2:$B$239,MATCH($X$2,Decisiones!$A$2:$A$239,0)),"") -> 46289 | I22: =IFERROR(INDEX(Decisiones!$D$2:$D$237,MATCH($X$2,Decisiones!$A$2:$A$239,0)),"") | Z22: D20030627 | AA22: 37799
A23: Tasa anterior | B23: Tasa anterior | C23: Tasa anterior | D23: Tasa anterior | E23: Movimiento (pb) | F23: Movimiento (pb) | G23: Movimiento (pb) | H23: Movimiento (pb) | I23: Nueva tasa | J23: Nueva tasa | K23: Nueva tasa | L23: Nueva tasa | Z23: D20030725 | AA23: 37827
A24: =IFERROR(INDEX(Decisiones!$F$2:$F$239,MATCH($X$2,Decisiones!$A$2:$A$239,0)),"") -> 6.5 | E24: =IFERROR(INDEX(Decisiones!$G$2:$G$239,MATCH($X$2,Decisiones!$A$2:$A$239,0)),"") -> 0 | I24: =IFERROR(INDEX(Decisiones!$H$2:$H$239,MATCH($X$2,Decisiones!$A$2:$A$239,0)),"") -> 6.5 | Z24: D20030822 | AA24: 37855
A25: Dirección | B25: Dirección | C25: Dirección | D25: Dirección | E25: ¿Fue unánime? | F25: ¿Fue unánime? | G25: ¿Fue unánime? | H25: ¿Fue unánime? | I25: Número de disensos | J25: Número de disensos | K25: Número de disensos | L25: Número de disensos | Z25: D20030926 | AA25: 37890
A26: =IFERROR(INDEX(Decisiones!$I$2:$I$239,MATCH($X$2,Decisiones!$A$2:$A$239,0)),"") -> Sin cambio | E26: =IFERROR(INDEX(Decisiones!$J$2:$J$239,MATCH($X$2,Decisiones!$A$2:$A$239,0)),"") -> Sí | I26: =IFERROR(INDEX(Decisiones!$K$2:$K$239,MATCH($X$2,Decisiones!$A$2:$A$239,0)),"") -> 0 | Z26: D20031024 | AA26: 37918
A27: Contexto histórico · cinco decisiones anteriores y cinco posteriores | Z27: D20031121 | AA27: 37946
A28: Fecha | B28: =INDEX(Decisiones!$B$2:$B$239,MAX(1,MIN(MATCH($X$2,Decisiones!$A$2:$A$239,0)-5,ROWS(Decisiones!$A$2:$A$239)-10))+0) -> 45834 | C28: =INDEX(Decisiones!$B$2:$B$239,MAX(1,MIN(MATCH($X$2,Decisiones!$A$2:$A$239,0)-5,ROWS(Decisiones!$A$2:$A$239)-10))+1) -> 45876 | D28: =INDEX(Decisiones!$B$2:$B$239,MAX(1,MIN(MATCH($X$2,Decisiones!$A$2:$A$239,0)-5,ROWS(Decisiones!$A$2:$A$239)-10))+2) -> 45925 | E28: =INDEX(Decisiones!$B$2:$B$239,MAX(1,MIN(MATCH($X$2,Decisiones!$A$2:$A$239,0)-5,ROWS(Decisiones!$A$2:$A$239)-10))+3) -> 45967 | F28: =INDEX(Decisiones!$B$2:$B$239,MAX(1,MIN(MATCH($X$2,Decisiones!$A$2:$A$239,0)-5,ROWS(Decisiones!$A$2:$A$239)-10))+4) -> 46009 | G28: =INDEX(Decisiones!$B$2:$B$239,MAX(1,MIN(MATCH($X$2,Decisiones!$A$2:$A$239,0)-5,ROWS(Decisiones!$A$2:$A$239)-10))+5) -> 46058 | H28: =INDEX(Decisiones!$B$2:$B$239,MAX(1,MIN(MATCH($X$2,Decisiones!$A$2:$A$239,0)-5,ROWS(Decisiones!$A$2:$A$239)-10))+6) -> 46107 | I28: =INDEX(Decisiones!$B$2:$B$239,MAX(1,MIN(MATCH($X$2,Decisiones!$A$2:$A$239,0)-5,ROWS(Decisiones!$A$2:$A$239)-10))+7) -> 46149 | J28: =INDEX(Decisiones!$B$2:$B$239,MAX(1,MIN(MATCH($X$2,Decisiones!$A$2:$A$239,0)-5,ROWS(Decisiones!$A$2:$A$239)-10))+8) -> 46198 | K28: =INDEX(Decisiones!$B$2:$B$239,MAX(1,MIN(MATCH($X$2,Decisiones!$A$2:$A$239,0)-5,ROWS(Decisiones!$A$2:$A$239)-10))+9) -> 46240 | L28: =INDEX(Decisiones!$B$2:$B$239,MAX(1,MIN(MATCH($X$2,Decisiones!$A$2:$A$239,0)-5,ROWS(Decisiones!$A$2:$A$239)-10))+10) -> 46289 | Z28: D20031211 | AA28: 37966
A29: Tasa | B29: =INDEX(Decisiones!$H$2:$H$239,MAX(1,MIN(MATCH($X$2,Decisiones!$A$2:$A$239,0)-5,ROWS(Decisiones!$A$2:$A$239)-10))+0) -> 8 | C29: =INDEX(Decisiones!$H$2:$H$239,MAX(1,MIN(MATCH($X$2,Decisiones!$A$2:$A$239,0)-5,ROWS(Decisiones!$A$2:$A$239)-10))+1) -> 7.75 | D29: =INDEX(Decisiones!$H$2:$H$239,MAX(1,MIN(MATCH($X$2,Decisiones!$A$2:$A$239,0)-5,ROWS(Decisiones!$A$2:$A$239)-10))+2) -> 7.5 | E29: =INDEX(Decisiones!$H$2:$H$239,MAX(1,MIN(MATCH($X$2,Decisiones!$A$2:$A$239,0)-5,ROWS(Decisiones!$A$2:$A$239)-10))+3) -> 7.25 | F29: =INDEX(Decisiones!$H$2:$H$239,MAX(1,MIN(MATCH($X$2,Decisiones!$A$2:$A$239,0)-5,ROWS(Decisiones!$A$2:$A$239)-10))+4) -> 7 | G29: =INDEX(Decisiones!$H$2:$H$239,MAX(1,MIN(MATCH($X$2,Decisiones!$A$2:$A$239,0)-5,ROWS(Decisiones!$A$2:$A$239)-10))+5) -> 7 | H29: =INDEX(Decisiones!$H$2:$H$239,MAX(1,MIN(MATCH($X$2,Decisiones!$A$2:$A$239,0)-5,ROWS(Decisiones!$A$2:$A$239)-10))+6) -> 6.75 | I29: =INDEX(Decisiones!$H$2:$H$239,MAX(1,MIN(MATCH($X$2,Decisiones!$A$2:$A$239,0)-5,ROWS(Decisiones!$A$2:$A$239)-10))+7) -> 6.5 | J29: =INDEX(Decisiones!$H$2:$H$239,MAX(1,MIN(MATCH($X$2,Decisiones!$A$2:$A$239,0)-5,ROWS(Decisiones!$A$2:$A$239)-10))+8) -> 6.5 | K29: =INDEX(Decisiones!$H$2:$H$239,MAX(1,MIN(MATCH($X$2,Decisiones!$A$2:$A$239,0)-5,ROWS(Decisiones!$A$2:$A$239)-10))+9) -> 6.5 | L29: =INDEX(Decisiones!$H$2:$H$239,MAX(1,MIN(MATCH($X$2,Decisiones!$A$2:$A$239,0)-5,ROWS(Decisiones!$A$2:$A$239)-10))+10) -> 6.5 | Z29: D20040123 | AA29: 38009
A30: Movimiento | B30: =IF(INDEX(Decisiones!$I$2:$I$239,MAX(1,MIN(MATCH($X$2,Decisiones!$A$2:$A$239,0)-5,ROWS(Decisiones!$A$2:$A$239)-10))+0)="Sube","↑",IF(INDEX(Decisiones!$I$2:$I$239,MAX(1,MIN(MATCH($X$2,Decisiones!$A$2:$A$239,0)-5,ROWS(Decisiones!$A$2:$A$239)-10))+0)="Baja","↓","=")) -> ↓ | C30: =IF(INDEX(Decisiones!$I$2:$I$239,MAX(1,MIN(MATCH($X$2,Decisiones!$A$2:$A$239,0)-5,ROWS(Decisiones!$A$2:$A$239)-10))+1)="Sube","↑",IF(INDEX(Decisiones!$I$2:$I$239,MAX(1,MIN(MATCH($X$2,Decisiones!$A$2:$A$239,0)-5,ROWS(Decisiones!$A$2:$A$239)-10))+1)="Baja","↓","=")) -> ↓ | D30: =IF(INDEX(Decisiones!$I$2:$I$239,MAX(1,MIN(MATCH($X$2,Decisiones!$A$2:$A$239,0)-5,ROWS(Decisiones!$A$2:$A$239)-10))+2)="Sube","↑",IF(INDEX(Decisiones!$I$2:$I$239,MAX(1,MIN(MATCH($X$2,Decisiones!$A$2:$A$239,0)-5,ROWS(Decisiones!$A$2:$A$239)-10))+2)="Baja","↓","=")) -> ↓ | E30: =IF(INDEX(Decisiones!$I$2:$I$239,MAX(1,MIN(MATCH($X$2,Decisiones!$A$2:$A$239,0)-5,ROWS(Decisiones!$A$2:$A$239)-10))+3)="Sube","↑",IF(INDEX(Decisiones!$I$2:$I$239,MAX(1,MIN(MATCH($X$2,Decisiones!$A$2:$A$239,0)-5,ROWS(Decisiones!$A$2:$A$239)-10))+3)="Baja","↓","=")) -> ↓ | F30: =IF(INDEX(Decisiones!$I$2:$I$239,MAX(1,MIN(MATCH($X$2,Decisiones!$A$2:$A$239,0)-5,ROWS(Decisiones!$A$2:$A$239)-10))+4)="Sube","↑",IF(INDEX(Decisiones!$I$2:$I$239,MAX(1,MIN(MATCH($X$2,Decisiones!$A$2:$A$239,0)-5,ROWS(Decisiones!$A$2:$A$239)-10))+4)="Baja","↓","=")) -> ↓ | G30: =IF(INDEX(Decisiones!$I$2:$I$239,MAX(1,MIN(MATCH($X$2,Decisiones!$A$2:$A$239,0)-5,ROWS(Decisiones!$A$2:$A$239)-10))+5)="Sube","↑",IF(INDEX(Decisiones!$I$2:$I$239,MAX(1,MIN(MATCH($X$2,Decisiones!$A$2:$A$239,0)-5,ROWS(Decisiones!$A$2:$A$239)-10))+5)="Baja","↓","=")) -> = | H30: =IF(INDEX(Decisiones!$I$2:$I$239,MAX(1,MIN(MATCH($X$2,Decisiones!$A$2:$A$239,0)-5,ROWS(Decisiones!$A$2:$A$239)-10))+6)="Sube","↑",IF(INDEX(Decisiones!$I$2:$I$239,MAX(1,MIN(MATCH($X$2,Decisiones!$A$2:$A$239,0)-5,ROWS(Decisiones!$A$2:$A$239)-10))+6)="Baja","↓","=")) -> ↓ | I30: =IF(INDEX(Decisiones!$I$2:$I$239,MAX(1,MIN(MATCH($X$2,Decisiones!$A$2:$A$239,0)-5,ROWS(Decisiones!$A$2:$A$239)-10))+7)="Sube","↑",IF(INDEX(Decisiones!$I$2:$I$239,MAX(1,MIN(MATCH($X$2,Decisiones!$A$2:$A$239,0)-5,ROWS(Decisiones!$A$2:$A$239)-10))+7)="Baja","↓","=")) -> ↓ | J30: =IF(INDEX(Decisiones!$I$2:$I$239,MAX(1,MIN(MATCH($X$2,Decisiones!$A$2:$A$239,0)-5,ROWS(Decisiones!$A$2:$A$239)-10))+8)="Sube","↑",IF(INDEX(Decisiones!$I$2:$I$239,MAX(1,MIN(MATCH($X$2,Decisiones!$A$2:$A$239,0)-5,ROWS(Decisiones!$A$2:$A$239)-10))+8)="Baja","↓","=")) -> = | K30: =IF(INDEX(Decisiones!$I$2:$I$239,MAX(1,MIN(MATCH($X$2,Decisiones!$A$2:$A$239,0)-5,ROWS(Decisiones!$A$2:$A$239)-10))+9)="Sube","↑",IF(INDEX(Decisiones!$I$2:$I$239,MAX(1,MIN(MATCH($X$2,Decisiones!$A$2:$A$239,0)-5,ROWS(Decisiones!$A$2:$A$239)-10))+9)="Baja","↓","=")) -> = | L30: =IF(INDEX(Decisiones!$I$2:$I$239,MAX(1,MIN(MATCH($X$2,Decisiones!$A$2:$A$239,0)-5,ROWS(Decisiones!$A$2:$A$239)-10))+10)="Sube","↑",IF(INDEX(Decisiones!$I$2:$I$239,MAX(1,MIN(MATCH($X$2,Decisiones!$A$2:$A$239,0)-5,ROWS(Decisiones!$A$2:$A$239)-10))+10)="Baja","↓","=")) -> = | Z30: D20040220 | AA30: 38037
A31: Decision_ID | B31: =INDEX(Decisiones!$A$2:$A$239,MAX(1,MIN(MATCH($X$2,Decisiones!$A$2:$A$239,0)-5,ROWS(Decisiones!$A$2:$A$239)-10))+0) -> D20250626 | C31: =INDEX(Decisiones!$A$2:$A$239,MAX(1,MIN(MATCH($X$2,Decisiones!$A$2:$A$239,0)-5,ROWS(Decisiones!$A$2:$A$239)-10))+1) -> D20250807 | D31: =INDEX(Decisiones!$A$2:$A$239,MAX(1,MIN(MATCH($X$2,Decisiones!$A$2:$A$239,0)-5,ROWS(Decisiones!$A$2:$A$239)-10))+2) -> D20250925 | E31: =INDEX(Decisiones!$A$2:$A$239,MAX(1,MIN(MATCH($X$2,Decisiones!$A$2:$A$239,0)-5,ROWS(Decisiones!$A$2:$A$239)-10))+3) -> D20251106 | F31: =INDEX(Decisiones!$A$2:$A$239,MAX(1,MIN(MATCH($X$2,Decisiones!$A$2:$A$239,0)-5,ROWS(Decisiones!$A$2:$A$239)-10))+4) -> D20251218 | G31: =INDEX(Decisiones!$A$2:$A$239,MAX(1,MIN(MATCH($X$2,Decisiones!$A$2:$A$239,0)-5,ROWS(Decisiones!$A$2:$A$239)-10))+5) -> D20260205 | H31: =INDEX(Decisiones!$A$2:$A$239,MAX(1,MIN(MATCH($X$2,Decisiones!$A$2:$A$239,0)-5,ROWS(Decisiones!$A$2:$A$239)-10))+6) -> D20260326 | I31: =INDEX(Decisiones!$A$2:$A$239,MAX(1,MIN(MATCH($X$2,Decisiones!$A$2:$A$239,0)-5,ROWS(Decisiones!$A$2:$A$239)-10))+7) -> D20260507 | J31: =INDEX(Decisiones!$A$2:$A$239,MAX(1,MIN(MATCH($X$2,Decisiones!$A$2:$A$239,0)-5,ROWS(Decisiones!$A$2:$A$239)-10))+8) -> D20260625 | K31: =INDEX(Decisiones!$A$2:$A$239,MAX(1,MIN(MATCH($X$2,Decisiones!$A$2:$A$239,0)-5,ROWS(Decisiones!$A$2:$A$239)-10))+9) -> D20260806 | L31: =INDEX(Decisiones!$A$2:$A$239,MAX(1,MIN(MATCH($X$2,Decisiones!$A$2:$A$239,0)-5,ROWS(Decisiones!$A$2:$A$239)-10))+10) -> D20260924 | Z31: D20040312 | AA31: 38058
Z32: D20040326 | AA32: 38072
A33: Integrante | B33: =TEXT(B28,"dd-mmm") -> 26-Jun | C33: =TEXT(C28,"dd-mmm") -> 07-Aug | D33: =TEXT(D28,"dd-mmm") -> 25-Sep | E33: =TEXT(E28,"dd-mmm") -> 06-Nov | F33: =TEXT(F28,"dd-mmm") -> 18-Dec | G33: =TEXT(G28,"dd-mmm") -> 05-Feb | H33: =TEXT(H28,"dd-mmm") -> 26-Mar | I33: =TEXT(I28,"dd-mmm") -> 07-May | ... L33: =TEXT(L28,"dd-mmm") -> 24-Sep | Z33: D20040423 | AA33: 38100
Z34: D20040427 | AA34: 38104
A35: =IF($M35="","",IFERROR(INDEX(Personas!$B$2:$B$30,MATCH($M35,Personas!$A$2:$A$30,0)),"?")) | B35: =IF($A35="","",IF(B$31="","",IF(COUNTIFS(Votaciones!$A$2:$A$346,B$31,Votaciones!$B$2:$B$346,$M35)>0,IF(COUNTIFS(Votaciones!$A$2:$A$346,B$31,Votaciones!$B$2:$B$346,$M35,Votaciones!$D$2:$D$346,"Consenso")>0,"●",IF(COUNTIFS(Votaciones!$A$2:$A$346,B$31,Votaciones!$B$2:$B$346,$M35,Votaciones!$D$2:$D$346,"Disenso restrictivo")>0,"▲",IF(COUNTIFS(Votaciones!$A$2:$A$346,B$31,Votaciones!$B$2:$B$346,$M35,Votaciones!$D$2:$D$346,"Disenso acomodaticio")>0,"▼","?"))),IF(COUNTIFS(Participacion_Junta!$A$2:$A$346,B$31,Participacion_Junta!$B$2:$B$346,$M35)>0,"○","?")))) | C35: =IF($A35="","",IF(C$31="","",IF(COUNTIFS(Votaciones!$A$2:$A$346,C$31,Votaciones!$B$2:$B$346,$M35)>0,IF(COUNTIFS(Votaciones!$A$2:$A$346,C$31,Votaciones!$B$2:$B$346,$M35,Votaciones!$D$2:$D$346,"Consenso")>0,"●",IF(COUNTIFS(Votaciones!$A$2:$A$346,C$31,Votaciones!$B$2:$B$346,$M35,Votaciones!$D$2:$D$346,"Disenso restrictivo")>0,"▲",IF(COUNTIFS(Votaciones!$A$2:$A$346,C$31,Votaciones!$B$2:$B$346,$M35,Votaciones!$D$2:$D$346,"Disenso acomodaticio")>0,"▼","?"))),IF(COUNTIFS(Participacion_Junta!$A$2:$A$346,C$31,Participacion_Junta!$B$2:$B$346,$M35)>0,"○","?")))) | D35: =IF($A35="","",IF(D$31="","",IF(COUNTIFS(Votaciones!$A$2:$A$346,D$31,Votaciones!$B$2:$B$346,$M35)>0,IF(COUNTIFS(Votaciones!$A$2:$A$346,D$31,Votaciones!$B$2:$B$346,$M35,Votaciones!$D$2:$D$346,"Consenso")>0,"●",IF(COUNTIFS(Votaciones!$A$2:$A$346,D$31,Votaciones!$B$2:$B$346,$M35,Votaciones!$D$2:$D$346,"Disenso restrictivo")>0,"▲",IF(COUNTIFS(Votaciones!$A$2:$A$346,D$31,Votaciones!$B$2:$B$346,$M35,Votaciones!$D$2:$D$346,"Disenso acomodaticio")>0,"▼","?"))),IF(COUNTIFS(Participacion_Junta!$A$2:$A$346,D$31,Participacion_Junta!$B$2:$B$346,$M35)>0,"○","?")))) | E35: =IF($A35="","",IF(E$31="","",IF(COUNTIFS(Votaciones!$A$2:$A$346,E$31,Votaciones!$B$2:$B$346,$M35)>0,IF(COUNTIFS(Votaciones!$A$2:$A$346,E$31,Votaciones!$B$2:$B$346,$M35,Votaciones!$D$2:$D$346,"Consenso")>0,"●",IF(COUNTIFS(Votaciones!$A$2:$A$346,E$31,Votaciones!$B$2:$B$346,$M35,Votaciones!$D$2:$D$346,"Disenso restrictivo")>0,"▲",IF(COUNTIFS(Votaciones!$A$2:$A$346,E$31,Votaciones!$B$2:$B$346,$M35,Votaciones!$D$2:$D$346,"Disenso acomodaticio")>0,"▼","?"))),IF(COUNTIFS(Participacion_Junta!$A$2:$A$346,E$31,Participacion_Junta!$B$2:$B$346,$M35)>0,"○","?")))) | F35: =IF($A35="","",IF(F$31="","",IF(COUNTIFS(Votaciones!$A$2:$A$346,F$31,Votaciones!$B$2:$B$346,$M35)>0,IF(COUNTIFS(Votaciones!$A$2:$A$346,F$31,Votaciones!$B$2:$B$346,$M35,Votaciones!$D$2:$D$346,"Consenso")>0,"●",IF(COUNTIFS(Votaciones!$A$2:$A$346,F$31,Votaciones!$B$2:$B$346,$M35,Votaciones!$D$2:$D$346,"Disenso restrictivo")>0,"▲",IF(COUNTIFS(Votaciones!$A$2:$A$346,F$31,Votaciones!$B$2:$B$346,$M35,Votaciones!$D$2:$D$346,"Disenso acomodaticio")>0,"▼","?"))),IF(COUNTIFS(Participacion_Junta!$A$2:$A$346,F$31,Participacion_Junta!$B$2:$B$346,$M35)>0,"○","?")))) | G35: =IF($A35="","",IF(G$31="","",IF(COUNTIFS(Votaciones!$A$2:$A$346,G$31,Votaciones!$B$2:$B$346,$M35)>0,IF(COUNTIFS(Votaciones!$A$2:$A$346,G$31,Votaciones!$B$2:$B$346,$M35,Votaciones!$D$2:$D$346,"Consenso")>0,"●",IF(COUNTIFS(Votaciones!$A$2:$A$346,G$31,Votaciones!$B$2:$B$346,$M35,Votaciones!$D$2:$D$346,"Disenso restrictivo")>0,"▲",IF(COUNTIFS(Votaciones!$A$2:$A$346,G$31,Votaciones!$B$2:$B$346,$M35,Votaciones!$D$2:$D$346,"Disenso acomodaticio")>0,"▼","?"))),IF(COUNTIFS(Participacion_Junta!$A$2:$A$346,G$31,Participacion_Junta!$B$2:$B$346,$M35)>0,"○","?")))) | H35: =IF($A35="","",IF(H$31="","",IF(COUNTIFS(Votaciones!$A$2:$A$346,H$31,Votaciones!$B$2:$B$346,$M35)>0,IF(COUNTIFS(Votaciones!$A$2:$A$346,H$31,Votaciones!$B$2:$B$346,$M35,Votaciones!$D$2:$D$346,"Consenso")>0,"●",IF(COUNTIFS(Votaciones!$A$2:$A$346,H$31,Votaciones!$B$2:$B$346,$M35,Votaciones!$D$2:$D$346,"Disenso restrictivo")>0,"▲",IF(COUNTIFS(Votaciones!$A$2:$A$346,H$31,Votaciones!$B$2:$B$346,$M35,Votaciones!$D$2:$D$346,"Disenso acomodaticio")>0,"▼","?"))),IF(COUNTIFS(Participacion_Junta!$A$2:$A$346,H$31,Participacion_Junta!$B$2:$B$346,$M35)>0,"○","?")))) | I35: =IF($A35="","",IF(I$31="","",IF(COUNTIFS(Votaciones!$A$2:$A$346,I$31,Votaciones!$B$2:$B$346,$M35)>0,IF(COUNTIFS(Votaciones!$A$2:$A$346,I$31,Votaciones!$B$2:$B$346,$M35,Votaciones!$D$2:$D$346,"Consenso")>0,"●",IF(COUNTIFS(Votaciones!$A$2:$A$346,I$31,Votaciones!$B$2:$B$346,$M35,Votaciones!$D$2:$D$346,"Disenso restrictivo")>0,"▲",IF(COUNTIFS(Votaciones!$A$2:$A$346,I$31,Votaciones!$B$2:$B$346,$M35,Votaciones!$D$2:$D$346,"Disenso acomodaticio")>0,"▼","?"))),IF(COUNTIFS(Participacion_Junta!$A$2:$A$346,I$31,Participacion_Junta!$B$2:$B$346,$M35)>0,"○","?")))) | ... L35: =IF($A35="","",IF(L$31="","",IF(COUNTIFS(Votaciones!$A$2:$A$346,L$31,Votaciones!$B$2:$B$346,$M35)>0,IF(COUNTIFS(Votaciones!$A$2:$A$346,L$31,Votaciones!$B$2:$B$346,$M35,Votaciones!$D$2:$D$346,"Consenso")>0,"●",IF(COUNTIFS(Votaciones!$A$2:$A$346,L$31,Votaciones!$B$2:$B$346,$M35,Votaciones!$D$2:$D$346,"Disenso restrictivo")>0,"▲",IF(COUNTIFS(Votaciones!$A$2:$A$346,L$31,Votaciones!$B$2:$B$346,$M35,Votaciones!$D$2:$D$346,"Disenso acomodaticio")>0,"▼","?"))),IF(COUNTIFS(Participacion_Junta!$A$2:$A$346,L$31,Participacion_Junta!$B$2:$B$346,$M35)>0,"○","?")))) | M35: =IFERROR(INDEX($B$351:$B$586,MATCH($X$2,$A$351:$A$586,0)),"") | Z35: D20040528 | AA35: 38135
A36: =IF($M36="","",IFERROR(INDEX(Personas!$B$2:$B$30,MATCH($M36,Personas!$A$2:$A$30,0)),"?")) | B36: =IF($A36="","",IF(B$31="","",IF(COUNTIFS(Votaciones!$A$2:$A$346,B$31,Votaciones!$B$2:$B$346,$M36)>0,IF(COUNTIFS(Votaciones!$A$2:$A$346,B$31,Votaciones!$B$2:$B$346,$M36,Votaciones!$D$2:$D$346,"Consenso")>0,"●",IF(COUNTIFS(Votaciones!$A$2:$A$346,B$31,Votaciones!$B$2:$B$346,$M36,Votaciones!$D$2:$D$346,"Disenso restrictivo")>0,"▲",IF(COUNTIFS(Votaciones!$A$2:$A$346,B$31,Votaciones!$B$2:$B$346,$M36,Votaciones!$D$2:$D$346,"Disenso acomodaticio")>0,"▼","?"))),IF(COUNTIFS(Participacion_Junta!$A$2:$A$346,B$31,Participacion_Junta!$B$2:$B$346,$M36)>0,"○","?")))) | C36: =IF($A36="","",IF(C$31="","",IF(COUNTIFS(Votaciones!$A$2:$A$346,C$31,Votaciones!$B$2:$B$346,$M36)>0,IF(COUNTIFS(Votaciones!$A$2:$A$346,C$31,Votaciones!$B$2:$B$346,$M36,Votaciones!$D$2:$D$346,"Consenso")>0,"●",IF(COUNTIFS(Votaciones!$A$2:$A$346,C$31,Votaciones!$B$2:$B$346,$M36,Votaciones!$D$2:$D$346,"Disenso restrictivo")>0,"▲",IF(COUNTIFS(Votaciones!$A$2:$A$346,C$31,Votaciones!$B$2:$B$346,$M36,Votaciones!$D$2:$D$346,"Disenso acomodaticio")>0,"▼","?"))),IF(COUNTIFS(Participacion_Junta!$A$2:$A$346,C$31,Participacion_Junta!$B$2:$B$346,$M36)>0,"○","?")))) | D36: =IF($A36="","",IF(D$31="","",IF(COUNTIFS(Votaciones!$A$2:$A$346,D$31,Votaciones!$B$2:$B$346,$M36)>0,IF(COUNTIFS(Votaciones!$A$2:$A$346,D$31,Votaciones!$B$2:$B$346,$M36,Votaciones!$D$2:$D$346,"Consenso")>0,"●",IF(COUNTIFS(Votaciones!$A$2:$A$346,D$31,Votaciones!$B$2:$B$346,$M36,Votaciones!$D$2:$D$346,"Disenso restrictivo")>0,"▲",IF(COUNTIFS(Votaciones!$A$2:$A$346,D$31,Votaciones!$B$2:$B$346,$M36,Votaciones!$D$2:$D$346,"Disenso acomodaticio")>0,"▼","?"))),IF(COUNTIFS(Participacion_Junta!$A$2:$A$346,D$31,Participacion_Junta!$B$2:$B$346,$M36)>0,"○","?")))) | E36: =IF($A36="","",IF(E$31="","",IF(COUNTIFS(Votaciones!$A$2:$A$346,E$31,Votaciones!$B$2:$B$346,$M36)>0,IF(COUNTIFS(Votaciones!$A$2:$A$346,E$31,Votaciones!$B$2:$B$346,$M36,Votaciones!$D$2:$D$346,"Consenso")>0,"●",IF(COUNTIFS(Votaciones!$A$2:$A$346,E$31,Votaciones!$B$2:$B$346,$M36,Votaciones!$D$2:$D$346,"Disenso restrictivo")>0,"▲",IF(COUNTIFS(Votaciones!$A$2:$A$346,E$31,Votaciones!$B$2:$B$346,$M36,Votaciones!$D$2:$D$346,"Disenso acomodaticio")>0,"▼","?"))),IF(COUNTIFS(Participacion_Junta!$A$2:$A$346,E$31,Participacion_Junta!$B$2:$B$346,$M36)>0,"○","?")))) | F36: =IF($A36="","",IF(F$31="","",IF(COUNTIFS(Votaciones!$A$2:$A$346,F$31,Votaciones!$B$2:$B$346,$M36)>0,IF(COUNTIFS(Votaciones!$A$2:$A$346,F$31,Votaciones!$B$2:$B$346,$M36,Votaciones!$D$2:$D$346,"Consenso")>0,"●",IF(COUNTIFS(Votaciones!$A$2:$A$346,F$31,Votaciones!$B$2:$B$346,$M36,Votaciones!$D$2:$D$346,"Disenso restrictivo")>0,"▲",IF(COUNTIFS(Votaciones!$A$2:$A$346,F$31,Votaciones!$B$2:$B$346,$M36,Votaciones!$D$2:$D$346,"Disenso acomodaticio")>0,"▼","?"))),IF(COUNTIFS(Participacion_Junta!$A$2:$A$346,F$31,Participacion_Junta!$B$2:$B$346,$M36)>0,"○","?")))) | G36: =IF($A36="","",IF(G$31="","",IF(COUNTIFS(Votaciones!$A$2:$A$346,G$31,Votaciones!$B$2:$B$346,$M36)>0,IF(COUNTIFS(Votaciones!$A$2:$A$346,G$31,Votaciones!$B$2:$B$346,$M36,Votaciones!$D$2:$D$346,"Consenso")>0,"●",IF(COUNTIFS(Votaciones!$A$2:$A$346,G$31,Votaciones!$B$2:$B$346,$M36,Votaciones!$D$2:$D$346,"Disenso restrictivo")>0,"▲",IF(COUNTIFS(Votaciones!$A$2:$A$346,G$31,Votaciones!$B$2:$B$346,$M36,Votaciones!$D$2:$D$346,"Disenso acomodaticio")>0,"▼","?"))),IF(COUNTIFS(Participacion_Junta!$A$2:$A$346,G$31,Participacion_Junta!$B$2:$B$346,$M36)>0,"○","?")))) | H36: =IF($A36="","",IF(H$31="","",IF(COUNTIFS(Votaciones!$A$2:$A$346,H$31,Votaciones!$B$2:$B$346,$M36)>0,IF(COUNTIFS(Votaciones!$A$2:$A$346,H$31,Votaciones!$B$2:$B$346,$M36,Votaciones!$D$2:$D$346,"Consenso")>0,"●",IF(COUNTIFS(Votaciones!$A$2:$A$346,H$31,Votaciones!$B$2:$B$346,$M36,Votaciones!$D$2:$D$346,"Disenso restrictivo")>0,"▲",IF(COUNTIFS(Votaciones!$A$2:$A$346,H$31,Votaciones!$B$2:$B$346,$M36,Votaciones!$D$2:$D$346,"Disenso acomodaticio")>0,"▼","?"))),IF(COUNTIFS(Participacion_Junta!$A$2:$A$346,H$31,Participacion_Junta!$B$2:$B$346,$M36)>0,"○","?")))) | I36: =IF($A36="","",IF(I$31="","",IF(COUNTIFS(Votaciones!$A$2:$A$346,I$31,Votaciones!$B$2:$B$346,$M36)>0,IF(COUNTIFS(Votaciones!$A$2:$A$346,I$31,Votaciones!$B$2:$B$346,$M36,Votaciones!$D$2:$D$346,"Consenso")>0,"●",IF(COUNTIFS(Votaciones!$A$2:$A$346,I$31,Votaciones!$B$2:$B$346,$M36,Votaciones!$D$2:$D$346,"Disenso restrictivo")>0,"▲",IF(COUNTIFS(Votaciones!$A$2:$A$346,I$31,Votaciones!$B$2:$B$346,$M36,Votaciones!$D$2:$D$346,"Disenso acomodaticio")>0,"▼","?"))),IF(COUNTIFS(Participacion_Junta!$A$2:$A$346,I$31,Participacion_Junta!$B$2:$B$346,$M36)>0,"○","?")))) | ... L36: =IF($A36="","",IF(L$31="","",IF(COUNTIFS(Votaciones!$A$2:$A$346,L$31,Votaciones!$B$2:$B$346,$M36)>0,IF(COUNTIFS(Votaciones!$A$2:$A$346,L$31,Votaciones!$B$2:$B$346,$M36,Votaciones!$D$2:$D$346,"Consenso")>0,"●",IF(COUNTIFS(Votaciones!$A$2:$A$346,L$31,Votaciones!$B$2:$B$346,$M36,Votaciones!$D$2:$D$346,"Disenso restrictivo")>0,"▲",IF(COUNTIFS(Votaciones!$A$2:$A$346,L$31,Votaciones!$B$2:$B$346,$M36,Votaciones!$D$2:$D$346,"Disenso acomodaticio")>0,"▼","?"))),IF(COUNTIFS(Participacion_Junta!$A$2:$A$346,L$31,Participacion_Junta!$B$2:$B$346,$M36)>0,"○","?")))) | M36: =IFERROR(INDEX($C$351:$C$586,MATCH($X$2,$A$351:$A$586,0)),"") | Z36: D20040625 | AA36: 38163
A37: =IF($M37="","",IFERROR(INDEX(Personas!$B$2:$B$30,MATCH($M37,Personas!$A$2:$A$30,0)),"?")) | B37: =IF($A37="","",IF(B$31="","",IF(COUNTIFS(Votaciones!$A$2:$A$346,B$31,Votaciones!$B$2:$B$346,$M37)>0,IF(COUNTIFS(Votaciones!$A$2:$A$346,B$31,Votaciones!$B$2:$B$346,$M37,Votaciones!$D$2:$D$346,"Consenso")>0,"●",IF(COUNTIFS(Votaciones!$A$2:$A$346,B$31,Votaciones!$B$2:$B$346,$M37,Votaciones!$D$2:$D$346,"Disenso restrictivo")>0,"▲",IF(COUNTIFS(Votaciones!$A$2:$A$346,B$31,Votaciones!$B$2:$B$346,$M37,Votaciones!$D$2:$D$346,"Disenso acomodaticio")>0,"▼","?"))),IF(COUNTIFS(Participacion_Junta!$A$2:$A$346,B$31,Participacion_Junta!$B$2:$B$346,$M37)>0,"○","?")))) | C37: =IF($A37="","",IF(C$31="","",IF(COUNTIFS(Votaciones!$A$2:$A$346,C$31,Votaciones!$B$2:$B$346,$M37)>0,IF(COUNTIFS(Votaciones!$A$2:$A$346,C$31,Votaciones!$B$2:$B$346,$M37,Votaciones!$D$2:$D$346,"Consenso")>0,"●",IF(COUNTIFS(Votaciones!$A$2:$A$346,C$31,Votaciones!$B$2:$B$346,$M37,Votaciones!$D$2:$D$346,"Disenso restrictivo")>0,"▲",IF(COUNTIFS(Votaciones!$A$2:$A$346,C$31,Votaciones!$B$2:$B$346,$M37,Votaciones!$D$2:$D$346,"Disenso acomodaticio")>0,"▼","?"))),IF(COUNTIFS(Participacion_Junta!$A$2:$A$346,C$31,Participacion_Junta!$B$2:$B$346,$M37)>0,"○","?")))) | D37: =IF($A37="","",IF(D$31="","",IF(COUNTIFS(Votaciones!$A$2:$A$346,D$31,Votaciones!$B$2:$B$346,$M37)>0,IF(COUNTIFS(Votaciones!$A$2:$A$346,D$31,Votaciones!$B$2:$B$346,$M37,Votaciones!$D$2:$D$346,"Consenso")>0,"●",IF(COUNTIFS(Votaciones!$A$2:$A$346,D$31,Votaciones!$B$2:$B$346,$M37,Votaciones!$D$2:$D$346,"Disenso restrictivo")>0,"▲",IF(COUNTIFS(Votaciones!$A$2:$A$346,D$31,Votaciones!$B$2:$B$346,$M37,Votaciones!$D$2:$D$346,"Disenso acomodaticio")>0,"▼","?"))),IF(COUNTIFS(Participacion_Junta!$A$2:$A$346,D$31,Participacion_Junta!$B$2:$B$346,$M37)>0,"○","?")))) | E37: =IF($A37="","",IF(E$31="","",IF(COUNTIFS(Votaciones!$A$2:$A$346,E$31,Votaciones!$B$2:$B$346,$M37)>0,IF(COUNTIFS(Votaciones!$A$2:$A$346,E$31,Votaciones!$B$2:$B$346,$M37,Votaciones!$D$2:$D$346,"Consenso")>0,"●",IF(COUNTIFS(Votaciones!$A$2:$A$346,E$31,Votaciones!$B$2:$B$346,$M37,Votaciones!$D$2:$D$346,"Disenso restrictivo")>0,"▲",IF(COUNTIFS(Votaciones!$A$2:$A$346,E$31,Votaciones!$B$2:$B$346,$M37,Votaciones!$D$2:$D$346,"Disenso acomodaticio")>0,"▼","?"))),IF(COUNTIFS(Participacion_Junta!$A$2:$A$346,E$31,Participacion_Junta!$B$2:$B$346,$M37)>0,"○","?")))) | F37: =IF($A37="","",IF(F$31="","",IF(COUNTIFS(Votaciones!$A$2:$A$346,F$31,Votaciones!$B$2:$B$346,$M37)>0,IF(COUNTIFS(Votaciones!$A$2:$A$346,F$31,Votaciones!$B$2:$B$346,$M37,Votaciones!$D$2:$D$346,"Consenso")>0,"●",IF(COUNTIFS(Votaciones!$A$2:$A$346,F$31,Votaciones!$B$2:$B$346,$M37,Votaciones!$D$2:$D$346,"Disenso restrictivo")>0,"▲",IF(COUNTIFS(Votaciones!$A$2:$A$346,F$31,Votaciones!$B$2:$B$346,$M37,Votaciones!$D$2:$D$346,"Disenso acomodaticio")>0,"▼","?"))),IF(COUNTIFS(Participacion_Junta!$A$2:$A$346,F$31,Participacion_Junta!$B$2:$B$346,$M37)>0,"○","?")))) | G37: =IF($A37="","",IF(G$31="","",IF(COUNTIFS(Votaciones!$A$2:$A$346,G$31,Votaciones!$B$2:$B$346,$M37)>0,IF(COUNTIFS(Votaciones!$A$2:$A$346,G$31,Votaciones!$B$2:$B$346,$M37,Votaciones!$D$2:$D$346,"Consenso")>0,"●",IF(COUNTIFS(Votaciones!$A$2:$A$346,G$31,Votaciones!$B$2:$B$346,$M37,Votaciones!$D$2:$D$346,"Disenso restrictivo")>0,"▲",IF(COUNTIFS(Votaciones!$A$2:$A$346,G$31,Votaciones!$B$2:$B$346,$M37,Votaciones!$D$2:$D$346,"Disenso acomodaticio")>0,"▼","?"))),IF(COUNTIFS(Participacion_Junta!$A$2:$A$346,G$31,Participacion_Junta!$B$2:$B$346,$M37)>0,"○","?")))) | H37: =IF($A37="","",IF(H$31="","",IF(COUNTIFS(Votaciones!$A$2:$A$346,H$31,Votaciones!$B$2:$B$346,$M37)>0,IF(COUNTIFS(Votaciones!$A$2:$A$346,H$31,Votaciones!$B$2:$B$346,$M37,Votaciones!$D$2:$D$346,"Consenso")>0,"●",IF(COUNTIFS(Votaciones!$A$2:$A$346,H$31,Votaciones!$B$2:$B$346,$M37,Votaciones!$D$2:$D$346,"Disenso restrictivo")>0,"▲",IF(COUNTIFS(Votaciones!$A$2:$A$346,H$31,Votaciones!$B$2:$B$346,$M37,Votaciones!$D$2:$D$346,"Disenso acomodaticio")>0,"▼","?"))),IF(COUNTIFS(Participacion_Junta!$A$2:$A$346,H$31,Participacion_Junta!$B$2:$B$346,$M37)>0,"○","?")))) | I37: =IF($A37="","",IF(I$31="","",IF(COUNTIFS(Votaciones!$A$2:$A$346,I$31,Votaciones!$B$2:$B$346,$M37)>0,IF(COUNTIFS(Votaciones!$A$2:$A$346,I$31,Votaciones!$B$2:$B$346,$M37,Votaciones!$D$2:$D$346,"Consenso")>0,"●",IF(COUNTIFS(Votaciones!$A$2:$A$346,I$31,Votaciones!$B$2:$B$346,$M37,Votaciones!$D$2:$D$346,"Disenso restrictivo")>0,"▲",IF(COUNTIFS(Votaciones!$A$2:$A$346,I$31,Votaciones!$B$2:$B$346,$M37,Votaciones!$D$2:$D$346,"Disenso acomodaticio")>0,"▼","?"))),IF(COUNTIFS(Participacion_Junta!$A$2:$A$346,I$31,Participacion_Junta!$B$2:$B$346,$M37)>0,"○","?")))) | ... L37: =IF($A37="","",IF(L$31="","",IF(COUNTIFS(Votaciones!$A$2:$A$346,L$31,Votaciones!$B$2:$B$346,$M37)>0,IF(COUNTIFS(Votaciones!$A$2:$A$346,L$31,Votaciones!$B$2:$B$346,$M37,Votaciones!$D$2:$D$346,"Consenso")>0,"●",IF(COUNTIFS(Votaciones!$A$2:$A$346,L$31,Votaciones!$B$2:$B$346,$M37,Votaciones!$D$2:$D$346,"Disenso restrictivo")>0,"▲",IF(COUNTIFS(Votaciones!$A$2:$A$346,L$31,Votaciones!$B$2:$B$346,$M37,Votaciones!$D$2:$D$346,"Disenso acomodaticio")>0,"▼","?"))),IF(COUNTIFS(Participacion_Junta!$A$2:$A$346,L$31,Participacion_Junta!$B$2:$B$346,$M37)>0,"○","?")))) | M37: =IFERROR(INDEX($D$351:$D$586,MATCH($X$2,$A$351:$A$586,0)),"") | Z37: D20040723 | AA37: 38191
